<?xml version="1.0" ?>
<!-- =================================================================================== -->
<!-- |    This document was autogenerated by xacro from iiwa_striker.urdf.xacro        | -->
<!-- |    EDITING THIS FILE BY HAND IS NOT RECOMMENDED                                 | -->
<!-- =================================================================================== -->
<robot name="iiwa_1">
  <material name="Black">
    <color rgba="0.0 0.0 0.0 1.0"/>
  </material>
  <material name="Blue">
    <color rgba="0.0 0.0 0.8 1.0"/>
  </material>
  <material name="Green">
    <color rgba="0.0 0.8 0.0 1.0"/>
  </material>
  <material name="Grey">
    <color rgba="0.4 0.4 0.4 1.0"/>
  </material>
  <material name="Orange">
    <color rgba="1.0 0.4235294117647059 0.0392156862745098 1.0"/>
  </material>
  <material name="Brown">
    <color rgba="0.8705882352941177 0.8117647058823529 0.7647058823529411 1.0"/>
  </material>
  <material name="Red">
    <color rgba="0.8 0.0 0.0 1.0"/>
  </material>
  <material name="White">
    <color rgba="1.0 1.0 1.0 1.0"/>
  </material>
  <material name="LightGrey">
    <color rgba="0.3 0.3 0.3 1.0"/>
  </material>
  <link name="iiwa_1/link_0">
    <visual>
      <origin rpy="0 0 0" xyz="0 0 0"/>
      <geometry>
        <mesh filename="meshes/visual/link_0.stl"/>
      </geometry>
      <material name="Grey"/>
    </visual>
    <collision>
      <origin rpy="0 0 0" xyz="0 0 0"/>
      <geometry>
        <mesh filename="meshes/collision/link_0.stl"/>
      </geometry>
    </collision>
  </link>
  <!-- joint between link_0 and link_1 -->
  <joint name="iiwa_1/joint_1" type="revolute">
    <parent link="iiwa_1/link_0"/>
    <child link="iiwa_1/link_1"/>
    <origin rpy="0 0 0" xyz="0 0 0.1575"/>
    <axis xyz="0 0 1"/>
    <limit effort="320" lower="-2.9670597283903604" upper="2.9670597283903604" velocity="1.4835298641951802"/>
    <safety_controller k_position="100" k_velocity="10" soft_lower_limit="-2.9321531433504737" soft_upper_limit="2.9321531433504737"/>
    <!--      <dynamics damping="0.24150"  friction="0.31909"/> &lt;!&ndash; ETH &ndash;&gt;-->
    <dynamics damping="0.330320" friction="0"/>
  </joint>
  <link name="iiwa_1/link_1">
    <inertial>
      <mass value="3.854820"/>
      <origin xyz="-0.098492 0.000000 0.069462" rpy="0.0 0.0 0.0"/>
      <inertia ixx="0.055704" ixy="0.000000" ixz="0.000356"
               iyy="0.056488" iyz="0.000000" izz="0.001462"/>
    </inertial>
    <visual>
      <origin rpy="0 0 0" xyz="0 0 0"/>
      <geometry>
        <mesh filename="meshes/visual/link_1.stl"/>
      </geometry>
      <material name="Orange"/>
    </visual>
    <collision>
      <origin rpy="0 0 0" xyz="0 0 0"/>
      <geometry>
        <mesh filename="meshes/collision/link_1.stl"/>
      </geometry>
    </collision>
  </link>
  <!-- joint between link_1 and link_2 -->
  <joint name="iiwa_1/joint_2" type="revolute">
    <parent link="iiwa_1/link_1"/>
    <child link="iiwa_1/link_2"/>
    <origin rpy="1.5707963267948966   0 3.141592653589793" xyz="0 0 0.2025"/>
    <axis xyz="0 0 1"/>
    <limit effort="320" lower="-2.0943951023931953" upper="2.0943951023931953" velocity="1.4835298641951802"/>
    <safety_controller k_position="100" k_velocity="10" soft_lower_limit="-2.0594885173533086" soft_upper_limit="2.0594885173533086"/>
    <!--      <dynamics damping="0.37328"  friction="0.18130"/> &lt;!&ndash; ETH &ndash;&gt;-->
    <dynamics damping="0.212160" friction="0"/>
  </joint>
  <link name="iiwa_1/link_2">
    <inertial>
      <mass value="5.773797"/>
      <origin xyz="-0.000687 -0.029334 0.119974" rpy="0.0 0.0 0.0"/>
      <inertia ixx="0.025239" ixy="0.003213" ixz="-0.000263"
               iyy="0.003716" iyz="0.001421" izz="0.023538"/>
    </inertial>
    <visual>
      <origin rpy="0 0 0" xyz="0 0 0"/>
      <geometry>
        <mesh filename="meshes/visual/link_2.stl"/>
      </geometry>
      <material name="Orange"/>
    </visual>
    <collision>
      <origin rpy="0 0 0" xyz="0 0 0"/>
      <geometry>
        <mesh filename="meshes/collision/link_2.stl"/>
      </geometry>
    </collision>
  </link>
  <!-- joint between link_2 and link_3 -->
  <joint name="iiwa_1/joint_3" type="revolute">
    <parent link="iiwa_1/link_2"/>
    <child link="iiwa_1/link_3"/>
    <origin rpy="1.5707963267948966 0 3.141592653589793" xyz="0 0.2045 0"/>
    <axis xyz="0 0 1"/>
    <limit effort="176" lower="-2.9670597283903604" upper="2.9670597283903604" velocity="1.7453292519943295"/>
    <safety_controller k_position="100" k_velocity="10" soft_lower_limit="-2.9321531433504737" soft_upper_limit="2.9321531433504737"/>
    <!--      <dynamics damping="0.11025"  friction="0.07302"/> &lt;!&ndash; ETH &ndash;&gt;-->
    <dynamics damping="0.100000" friction="0"/>
  </joint>
  <link name="iiwa_1/link_3">
    <inertial>
      <mass value="5.953188"/>
      <origin xyz="0.000160 0.063306 0.043455" rpy="0.0 0.0 0.0"/>
      <inertia ixx="0.016829" ixy="0.000286" ixz="0.000417"
               iyy="0.011761" iyz="-0.005257" izz="0.006149"/>
    </inertial>
    <visual>
      <origin rpy="0 0 0" xyz="0 0 0"/>
      <geometry>
        <mesh filename="meshes/visual/link_3.stl"/>
      </geometry>
      <material name="Orange"/>
    </visual>
    <collision>
      <origin rpy="0 0 0" xyz="0 0 0"/>
      <geometry>
        <mesh filename="meshes/collision/link_3.stl"/>
      </geometry>
    </collision>
  </link>
  <!-- joint between link_3 and link_4 -->
  <joint name="iiwa_1/joint_4" type="revolute">
    <parent link="iiwa_1/link_3"/>
    <child link="iiwa_1/link_4"/>
    <origin rpy="1.5707963267948966 0 0" xyz="0 0 0.2155"/>
    <axis xyz="0 0 1"/>
    <limit effort="176" lower="-2.0943951023931953" upper="2.0943951023931953" velocity="1.3089969389957472"/>
    <safety_controller k_position="100" k_velocity="10" soft_lower_limit="-2.0594885173533086" soft_upper_limit="2.0594885173533086"/>
    <!--      <dynamics damping="0.10000"  friction="0.17671"/> &lt;!&ndash; ETH &ndash;&gt;-->
    <dynamics damping="0.219041" friction="0"/>
  </joint>
  <link name="iiwa_1/link_4">
    <inertial>
      <mass value="3.448720"/>
      <origin xyz="-0.000066 0.028782 0.116070" rpy="0.0 0.0 0.0"/>
      <inertia ixx="0.019103" ixy="0.000081" ixz="-0.000175"
               iyy="0.016046" iyz="0.001274" izz="0.003551"/>
    </inertial>
    <visual>
      <origin rpy="0 0 0" xyz="0 0 0"/>
      <geometry>
        <mesh filename="meshes/visual/link_4.stl"/>
      </geometry>
      <material name="Orange"/>
    </visual>
    <collision>
      <origin rpy="0 0 0" xyz="0 0 0"/>
      <geometry>
        <mesh filename="meshes/collision/link_4.stl"/>
      </geometry>
    </collision>
  </link>
  <!-- joint between link_4 and link_5 -->
  <joint name="iiwa_1/joint_5" type="revolute">
    <parent link="iiwa_1/link_4"/>
    <child link="iiwa_1/link_5"/>
    <origin rpy="-1.5707963267948966 3.141592653589793 0" xyz="0 0.1845 0"/>
    <axis xyz="0 0 1"/>
    <limit effort="110" lower="-2.9670597283903604" upper="2.9670597283903604" velocity="2.2689280275926285"/>
    <safety_controller k_position="100" k_velocity="10" soft_lower_limit="-2.9321531433504737" soft_upper_limit="2.9321531433504737"/>
    <!--      <dynamics damping="0.10000"  friction="0.03463"/> &lt;!&ndash; ETH &ndash;&gt;-->
    <dynamics damping="0.185923" friction="0"/>
  </joint>
  <link name="iiwa_1/link_5">
    <inertial>
      <mass value="4.007168"/>
      <origin xyz="-0.000036 0.065820 0.034909" rpy="0.0 0.0 0.0"/>
      <inertia ixx="0.009814" ixy="-0.000066" ixz="-0.000189"
               iyy="0.008728" iyz="-0.001553" izz="0.001388"/>
    </inertial>
    <visual>
      <origin rpy="0 0 0" xyz="0 0 0"/>
      <geometry>
        <mesh filename="meshes/visual/link_5.stl"/>
      </geometry>
      <material name="Orange"/>
    </visual>
    <collision>
      <origin rpy="0 0 0" xyz="0 0 0"/>
      <geometry>
        <mesh filename="meshes/collision/link_5.stl"/>
      </geometry>
    </collision>
  </link>
  <!-- joint between link_5 and link_6 -->
  <joint name="iiwa_1/joint_6" type="revolute">
    <parent link="iiwa_1/link_5"/>
    <child link="iiwa_1/link_6"/>
    <origin rpy="1.5707963267948966 0 0" xyz="0 0 0.2155"/>
    <axis xyz="0 0 1"/>
    <limit effort="40" lower="-2.0943951023931953" upper="2.0943951023931953" velocity="2.356194490192345"/>
    <safety_controller k_position="100" k_velocity="10" soft_lower_limit="-2.0594885173533086" soft_upper_limit="2.0594885173533086"/>
    <!--      <dynamics damping="0.12484"  friction="0.13391"/> &lt;!&ndash; ETH &ndash;&gt;-->
    <dynamics damping="0.100000" friction="0"/>
  </joint>
  <link name="iiwa_1/link_6">
    <inertial>
      <mass value="2.415840"/>
      <origin xyz="0.000723 0.019241 0.073756" rpy="0.0 0.0 0.0"/>
      <inertia ixx="0.002321" ixy="0.000637" ixz="0.000045"
               iyy="0.000980" iyz="-0.000262" izz="0.002200"/>
    </inertial>
    <visual>
      <origin rpy="0 0 0" xyz="0 0 0"/>
      <geometry>
        <mesh filename="meshes/visual/link_6.stl"/>
      </geometry>
      <material name="Orange"/>
    </visual>
    <collision>
      <origin rpy="0 0 0" xyz="0 0 0"/>
      <geometry>
        <mesh filename="meshes/collision/link_6.stl"/>
      </geometry>
    </collision>
  </link>
  <!-- joint between link_6 and link_7 -->
  <joint name="iiwa_1/joint_7" type="revolute">
    <parent link="iiwa_1/link_6"/>
    <child link="iiwa_1/link_7"/>
    <origin rpy="-1.5707963267948966 3.141592653589793 0" xyz="0 0.081 0"/>
    <axis xyz="0 0 1"/>
    <limit effort="40" lower="-3.0543261909900763" upper="3.0543261909900763" velocity="2.356194490192345"/>
    <safety_controller k_position="100" k_velocity="10" soft_lower_limit="-3.01941960595019" soft_upper_limit="3.01941960595019"/>
    <!--      <dynamics damping="0.10000"  friction="0.08710"/> &lt;!&ndash; ETH &ndash;&gt;-->
    <dynamics damping="0.100000" friction="0"/>
  </joint>
  <link name="iiwa_1/link_7">
    <inertial>
      <mass value="1.107339"/>
      <origin xyz="0.001207 0.001384 -0.000630" rpy="0.0 0.0 0.0"/>
      <inertia ixx="0.000765" ixy="0.000276" ixz="-0.000333"
               iyy="0.001042" iyz="0.000211" izz="0.000818"/>
    </inertial>
    <visual>
      <origin rpy="0 0 0" xyz="0 0 0"/>
      <geometry>
        <mesh filename="meshes/visual/link_7.stl"/>
      </geometry>
      <material name="Grey"/>
    </visual>
    <collision>
      <origin rpy="0 0 0" xyz="0 0 0"/>
      <geometry>
        <mesh filename="meshes/collision/link_7.stl"/>
      </geometry>
    </collision>
  </link>
  <joint name="iiwa_1/joint_ee" type="fixed">
    <parent link="iiwa_1/link_7"/>
    <child link="iiwa_1/link_ee"/>
    <origin rpy="0 0 0" xyz="0 0 0.07"/>
  </joint>
  <link name="iiwa_1/link_ee">
    <inertial>
      <origin xyz="0 0 0" rpy="0 0 0"/>
      <mass value="0.01"/>
      <inertia ixx="0.00008" ixy="0.0" ixz="0.0" iyy="0.00008" iyz="0.0" izz="0.0001"/>
    </inertial>
  </link>
  <joint name="iiwa_1/striker" type="fixed">
    <parent link="iiwa_1/link_ee"/>
    <child link="iiwa_1/striker_base"/>
    <origin rpy="0 0 0" xyz="0.0 0.0 0.0"/>
  </joint>
  <link name="iiwa_1/striker_base">
    <inertial>
      <origin xyz="0 0 0" rpy="0 0 0.25"/>
      <mass value="0.1"/>
      <inertia ixx="0.002" ixy="0.0" ixz="0.0" iyy="0.002" iyz="0.0" izz="0.00001"/>
    </inertial>
    <visual>
      <origin rpy="0 0.0 0" xyz="0 0 0"/>
      <geometry>
        <mesh filename="meshes/striker/visual/EE_arm.stl"/>
      </geometry>
      <material name="LightGrey"/>
    </visual>
    <collision>
      <origin rpy="0 0 0" xyz="0 0 0"/>
      <geometry>
        <mesh filename="meshes/striker/collision/EE_arm_collision.stl"/>
      </geometry>
    </collision>
  </link>
  <joint name="iiwa_1/striker_tip" type="fixed">
    <parent link="iiwa_1/striker_base"/>
    <child link="iiwa_1/striker_tip"/>
    <origin rpy="0 0 0" xyz="0.0 0.0 0.515"/>
  </joint>
  <link name="iiwa_1/striker_tip">
    <inertial>
      <origin xyz="0 0 0" rpy="0 0 0"/>
      <mass value="0.1"/>
      <inertia ixx="0.0005" ixy="0.0" ixz="0.0" iyy="0.0005" iyz="0.0" izz="0.0005"/>
    </inertial>
    <visual>
      <origin rpy="0.0 0.0 0" xyz="0 0.0 0.0"/>
      <geometry>
        <mesh filename="assets/EE_mallet_foam.stl"/>
      </geometry>
      <material name="LightGrey"/>
    </visual>
    <collision>
      <origin rpy="0.0 0.0 0" xyz="0 0.0 0.0505"/>
      <geometry>
        <cylinder radius="0.04815" length="0.06" />
      </geometry>
    </collision>
  </link>
</robot>
